import org.junit.Test;
import static org.junit.Assert.*;

public class FlawedCodeTests5 {

    @Test
    public void testFlawedCode1() {
        // Test division by zero error
        try {
            FlawedCode1.main(null);
            fail("Expected ArithmeticException for division by zero");
        } catch (ArithmeticException e) {
            // Expected exception
        }

        // Test array index out of bounds error
        try {
            FlawedCode1.main(null);
            fail("Expected ArrayIndexOutOfBoundsException");
        } catch (ArrayIndexOutOfBoundsException e) {
            // Expected exception
        }

        // Test null pointer exception
        try {
            FlawedCode1.main(null);
            fail("Expected NullPointerException");
        } catch (NullPointerException e) {
            // Expected exception
        }
    }

    @Test
    public void testFlawedCode2() {
        // Test array index out of bounds error
        try {
            FlawedCode2.main(null);
            fail("Expected ArrayIndexOutOfBoundsException");
        } catch (ArrayIndexOutOfBoundsException e) {
            // Expected exception
        }

        // Test division by zero error
        try {
            FlawedCode2.main(null);
            fail("Expected ArithmeticException for division by zero");
        } catch (ArithmeticException e) {
            // Expected exception
        }

        // Test null pointer exception
        try {
            FlawedCode2.main(null);
            fail("Expected NullPointerException");
        } catch (NullPointerException e) {
            // Expected exception
        }

        // Test string index out of bounds error
        try {
            FlawedCode2.main(null);
            fail("Expected StringIndexOutOfBoundsException");
        } catch (StringIndexOutOfBoundsException e) {
            // Expected exception
        }
    }

    @Test
    public void testFlawedCode3() {
        // Test null pointer exception
        try {
            FlawedCode3.main(null);
            fail("Expected NullPointerException");
        } catch (NullPointerException e) {
            // Expected exception
        }

        // Test division by zero error
        try {
            FlawedCode3.main(null);
            fail("Expected ArithmeticException for division by zero");
        } catch (ArithmeticException e) {
            // Expected exception
        }

        // Test array index out of bounds error
        try {
            FlawedCode3.main(null);
            fail("Expected ArrayIndexOutOfBoundsException");
        } catch (ArrayIndexOutOfBoundsException e) {
            // Expected exception
        }
    }

    @Test
    public void testFlawedCode4() {
        // Test array index out of bounds error
        try {
            FlawedCode4.main(null);
            fail("Expected ArrayIndexOutOfBoundsException");
        } catch (ArrayIndexOutOfBoundsException e) {
            // Expected exception
        }

        // Test arithmetic exception for division by zero
        try {
            FlawedCode4.main(null);
            fail("Expected ArithmeticException for division by zero");
        } catch (ArithmeticException e) {
            // Expected exception
        }

        // Test null pointer exception
        try {
            FlawedCode4.main(null);
            fail("Expected NullPointerException");
        } catch (NullPointerException e) {
            // Expected exception
        }
    }

    @Test
    public void testFlawedCode5() {
        // Test array index out of bounds error
        try {
            FlawedCode5.main(null);
            fail("Expected ArrayIndexOutOfBoundsException");
        } catch (ArrayIndexOutOfBoundsException e) {
            // Expected exception
        }

        // Test arithmetic exception for division by zero
        try {
            FlawedCode5.main(null);
            fail("Expected ArithmeticException for division by zero");
        } catch (ArithmeticException e) {
            // Expected exception
        }

        // Test null pointer exception
        try {
            FlawedCode5.main(null);
            fail("Expected NullPointerException");
        } catch (NullPointerException e) {
            // Expected exception
        }
    }
}
